# 예외 처리

## 예외

#### 예외 (Exception)

>python, javascript
>
>프로그램에 구문적인 에러는 없지만 실행하는 동안 발생할 수 있는 잘못된 상황을 의미한다.

* 발생한 예외를 처리하는 코드가 준비되어 있는지 확인하고 준비되어 있는 예외처리 코드를 실행한다.
* 예외처리 코드가 준비된 상황이 아니면 에러를 발생시키고 처리를 종료한다.

#### 에러 (Error)

>python, javascript, R
>
>구문(신택스)적으로 잘못된 것이 인식되면 에러를 발생시키고 처리를 종료한다.



#### 예외 처리 구문

* try ~ except들 ~ else ~ finally

```python
try:
	예외가 발생할 가능성이 있는 블록

except 처리하려는 예외명:					# 예외가 발생하면
	예외 처리 코드 블록
	
else:									 # 예외가 발생하지 않으면
	예외가 발생하지 않았을 때 수행되는 코드
	
finally:
	예외 발생 여부와 관계없이 수행되는 코드 블록
```



#### 예외

* 프로그램 코드는 이상이 없으나 실행 중에 불가피하게 발생하는 문제

```python
str = "80점"
score = int(str)
print(score)
print("작업완료")

#실행 결과
Traceback (most recent call last):
  File "<input>", line 2, in <module>
ValueError: invalid literal for int() with base 10: '80점'

```



#### 예외 처리

* 간단하게 **try: except:** 까지만 사용하는 것도 가능

```python
str = '80점'
try:
	score = int(str)
	print(score)
except:
	print("예외가 발생했습니다.")
print("작업완료")

#실행 결과
예외가 발생했습니다.
작업완료
```

* 예외가 발생하지 않으면 except 블록을 무시하고 다음 문장 실행
* 상황 자체를 해결하지는 않지만, 예외 인식/처리 기회를 제공함
* 예외 처리 구문을 루프로 감싸면 무엇이 잘못되었는지 알려줌
  * 전체를 무한 루프로 감싸 예외 발생 시 다시 루프 선두로 돌아감



#### 예외의 종류

| 예외              | 설명                                                         |
| ----------------- | ------------------------------------------------------------ |
| NameError         | 명칭이 발견되지 않는다. 초기화하지 않은 변수를 사용할 때 발생한다. |
| ValueError        | 타입은 맞지만 값의 형식이 잘못되었다.                        |
| ZeroDivisionError | 0으로 나누었다                                               |
| IndexError        | 첨자가 범위를 벗어났다.                                      |
| TypeError         | 타입이 맞지 않다. 숫자가 필요하내 곳에 문자열을 사용한 경우 등이다. |

```python
str = "89"
try:
	score = int(str)
	print(score)
	a = str[5]
except ValueError:
	print("점수의 형식이 잘못되었습니다.")
except IndexError:
	print("첨자 범위를 벗어났습니다.")
print("작업완료")

#실행 결과
89
첨자 범위를 벗어났습니다.
작업완료
```

* str[5]에서 IndexError 예외 발생
* except 블록이 아무리 많아도 먼저 발생한 예외에 맞는 하나만 선택됨
* 두 개 이상 괄호로 묶어 except 블록에서 동시에 받기 가능

```python
except(ValueError, IndexError):
	print("점수의 형식이나 첨자가 잘못되었습니다.")
```



#### raise 명령

* 고의적으로 예외를 발생시킨다.
* 작업을 위한 선결조건이 맞지 않거나 문제가 발생할 경우 호출원으로 사용

```python
def calcsum(n):
	if n < 0:
		raise ValueError
	sum = 0
	for i in range(n+1):
		sum += i
	return sum
	
try:
	print("~10 =",calcsum(10))
	print("~10 =",calcsum(-5))
except ValueError:
	print("입력값이 잘못되었습니다.")

#실행 결과
~10 = 55
입력값이 잘못되었습니다.
```



* 특이값을 리턴하는 방식으로도 가능
  * 리턴 값 점검에 철저할 것

```python
def calcsum(n):
	if n < 0:
		return -1
	sum = 0
	for i in range(n+1):
		sum += i
	return sum
	
result = calcsum(10)
if result == -1:
	print("입력값이 잘못되었습니다.")
else:
	print("~10 =",result)
	
result = calcsum(5)
if result == -1:
	print("입력값이 잘못되었습니다.")
else:
	print("~-5 =",result)

#실행 결과
~10 = 55
입력값이 잘못되었습니다.
```



#### finally 블록

* 예외 발생 여부와 무관하게 반드시 실행해야 할 명령 지정

```python
try:
	print("네트워크 접속")
	a = 2/0
	print("네트워크 통신 수행")
finally:
	print("접속 해제")
print("작업 완료")

#실행 결과
네트워크 접속
접속 해제
Traceback (most recent call last):
  File "<input>", line 3, in <module>
ZeroDivisionError: division by zero

```



#### assert 문장

* 프로그램의 현재 상태가 맞는지 확인
* assert 조건, 메세지

```python
score = 128
assert score <= 100,'점수는 100이하여야 합니다.'
print(score)

#실행 결과
Traceback (most recent call last):
  File "<input>", line 2, in <module>
AssertionError: 점수는 100이하여야 합니다.
```

